Workbook
Name TRANSMUTATION_TABLE: '[1]DO NOT DELETE'!$G$2:$J$42

Sheet ET-1B
B1: Name | D1: Name | E1: FEB.05 | F1: FEB.06 | G1: FEB.07 | H1: Q1.FEB7 | I1: FEB.12 | J1: FEB.13 | K1: FEB.14 | L1: FEB.19 | M1: FEB.20 | N1: Q2.FEB20 | O1: FEB.21 | P1: FEB.26 | Q1: FEB.27 | R1: FEB.27
A2: 1 | B2: Abobo | C2: Precious-Zennah | D2: Abobo, Precious-Zennah B. | E2: 18 | F2: 18 | G2: 18 | H2: 15 | I2: 20 | J2: 20 | K2: 18 | L2: 20 | M2: 20 | N2: 4 | O2: 18 | P2: 20 | Q2: 20
A3: 2 | B3: Agustin | C3: Jackie Lyn | D3: Agustin, Jackie Lyn C. | E3: 18 | F3: 18 | G3: 18 | H3: 15 | I3: 20 | J3: 20 | K3: 0 | L3: 0 | M3: 20 | N3: 4 | O3: 18 | P3: 20 | Q3: 20
A4: 3 | B4: Barrozo | C4: Christian Edward | D4: Barrozo, Christian Edward C. | E4: 18 | F4: 18 | G4: 18 | H4: 3 | I4: 18 | J4: 13 | K4: 18 | L4: 18 | M4: 20 | N4: 2 | O4: 0 | P4: 18 | Q4: 18
A5: 4 | B5: Benitez | C5: Joshua | D5: Benitez, Joshua F. | E5: 18 | F5: 18 | G5: 18 | H5: 13 | I5: 20 | J5: 20 | K5: 18 | L5: 20 | M5: 20 | N5: 4 | O5: 18 | P5: 20 | Q5: 20
A6: 5 | B6: Briñes | C6: Jiro Miguel | D6: Briñes, Jiro Miguel M. | E6: 18 | F6: 18 | G6: 18 | H6: 9 | I6: 20 | J6: 20 | K6: 18 | L6: 20 | M6: 20 | N6: 4 | O6: 18 | P6: 20 | Q6: 20
A7: 6 | B7: Busante | C7: Bryan Jerick | D7: Busante, Bryan Jerick | E7: 18 | F7: 18 | G7: 18 | H7: 14 | I7: 20 | J7: 15 | K7: 18 | L7: 20 | M7: 20 | N7: 3 | O7: 18 | P7: 20 | Q7: 20
A8: 7 | B8: Dajuya | C8: Rachel | D8: Dajuya, Rachel P. | E8: 18 | F8: 18 | G8: 18 | H8: 6 | I8: 15 | J8: 20 | K8: 18 | L8: 15 | M8: 20 | N8: 4 | O8: 18 | P8: 0 | Q8: 20
A9: 8 | B9: Diestro | C9: Daniel | D9: Diestro, Daniel M. | E9: 18 | F9: 18 | G9: 18 | H9: 13 | I9: 20 | J9: 20 | K9: 18 | L9: 20 | M9: 20 | N9: 3 | O9: 18 | P9: 0 | Q9: 20
A10: 9 | B10: Dionisio | C10: Michaella | D10: Dionisio, Michaella M. | E10: 18 | F10: 18 | G10: 18 | H10: 9 | I10: 20 | J10: 20 | K10: 18 | L10: 20 | M10: 20 | N10: 6 | O10: 18 | P10: 20 | Q10: 20
A11: 10 | B11: Dovales | C11: Riellyn Joy | D11: Dovales, Riellyn Joy E. | E11: 0 | F11: 0 | G11: 18 | H11: 7 | I11: 20 | J11: 15 | K11: 18 | L11: 0 | M11: 20 | N11: 3 | O11: 18 | P11: 15 | Q11: 20
A12: 11 | B12: Eugenio | C12: Kirk Benedict | D12: Eugenio, Kirk Benedict O. | E12: 0 | F12: 18 | G12: 18 | H12: 13 | I12: 18 | J12: 20 | K12: 18 | L12: 0 | M12: 13 | N12: 3 | O12: 18 | P12: 0 | Q12: 18
A13: 12 | B13: Francisco | C13: Reign | D13: Francisco, Reign T. | E13: 18 | F13: 18 | G13: 18 | H13: 11 | I13: 20 | J13: 18 | K13: 18 | L13: 18 | M13: 13 | O13: 18 | P13: 0 | Q13: 13
A14: 13 | B14: Herrera | C14: Rednash | D14: Herrera, Rednash T. | E14: 18 | F14: 18 | G14: 18 | H14: 11 | I14: 15 | J14: 20 | K14: 18 | L14: 0 | M14: 20 | N14: 3 | O14: 18 | P14: 0 | Q14: 20
A15: 14 | B15: Matuguina | C15: Rhamil | D15: Matuguina, Rhamil C. | E15: 18 | F15: 18 | G15: 18 | H15: 10 | I15: 20 | J15: 15 | K15: 18 | L15: 20 | M15: 20 | N15: 8 | O15: 18 | P15: 20 | Q15: 20
A16: 15 | B16: Reyes | C16: Daniell Joseph | D16: Reyes, Daniell Joseph F. | E16: 18 | F16: 18 | G16: 18 | H16: 16 | I16: 18 | J16: 18 | K16: 18 | L16: 18 | M16: 0 | O16: 18 | P16: 18 | Q16: 18
A17: 16 | B17: Rollon | C17: Karyl | D17: Rollon, Karyl C. | E17: 18 | F17: 18 | G17: 18 | H17: 12 | I17: 20 | J17: 0 | K17: 18 | L17: 18 | M17: 18 | N17: 5 | O17: 0 | P17: 18 | Q17: 18
A18: 17 | B18: Sacdalan | C18: Joshrie | D18: Sacdalan, Joshrie O. | E18: 18 | F18: 18 | G18: 18 | H18: 15 | I18: 20 | J18: 20 | K18: 18 | L18: 20 | M18: 20 | N18: 3 | O18: 18 | P18: 20 | Q18: 20
A19: 18 | B19: Sangco | C19: Jethro | D19: Sangco, Jethro C. | E19: 18 | F19: 18 | G19: 18 | H19: 12 | I19: 0 | J19: 20 | K19: 18 | L19: 20 | M19: 20 | N19: 5 | O19: 18 | P19: 20 | Q19: 20
A20: 19 | B20: Ubalde | C20: Ronald Aheron | D20: Ubalde, Ronald Aehron B. | E20: 18 | F20: 18 | G20: 18 | H20: 13 | I20: 18 | J20: 20 | K20: 0 | L20: 15 | M20: 20 | N20: 5 | O20: 0 | P20: 20 | Q20: 20

Sheet GRADES
A1: Class Record
A3: (Pursuant to Deped Order 8 series of 2015)
C4: REGION | G4: NCR | L4: DIVISION | O4: MANILA
B5: SCHOOL NAME | G5: TUP MANILA | T5: SCHOOL ID | X5: TUPM-24-12506 | AD5: SCHOOL YEAR | AG5: 2024-2025
A7: FIRST QUARTER | F7: GRADE & SECTION: | K7: BTVTED-ET | Q7: TEACHER: | S7: Prof. Izhar Daniel Dantes | AC7: SUBJECT: | AG7: ICT1EL
B8: LEARNERS' NAMES | F8: LAB ACTIVITIES (60%) | S8: ATTENDANCE (40%) | AF8: QUARTERLY ASSESSMENT (20%) | AI8: Initial | AJ8: Quarterly
F9: 1 | G9: 2 | H9: 3 | I9: 4 | J9: 5 | K9: 6 | L9: 7 | M9: 8 | N9: 9 | O9: 10 | P9: Total | Q9: PS | R9: WS | S9: 1 | T9: 2 | U9: 3 | V9: 4 | W9: 5 | X9: 6 | Y9: 7 | Z9: 8 | AA9: 9 | AB9: 10 | AC9: Total | AD9: PS | AE9: WS | AF9: 1 | AG9: PS | AH9: WS | AI9: Grade | AJ9: Grade
B10: HIGHEST POSSIBLE SCORE | F10: 50 | G10: 50 | H10: 35 | I10: 35 | J10: 35 | K10: 50 | L10: 35 | P10: =IF(COUNT($F10:$O10)=0,"",SUM($F10:$O10)) -> 290 | Q10: 100 | R10: 0.6 | S10: 20 | T10: 20 | U10: 20 | V10: 20 | W10: 20 | X10: 20 | Y10: 20 | Z10: 20 | AA10: 20 | AB10: 20 | AC10: =IF(COUNT($S10:$AB10)=0,"",SUM($S10:$AB10)) -> 200 | AD10: 100 | AE10: 0.4 | AF10: 100 | AG10: 100 | AH10: 0.2
B11: MALE
A12: 1 | B12: Barrozo, Christian Edward C. | F12: 40 | G12: 39 | H12: 20 | I12: 12 | J12: 33 | K12: 50 | L12: 29 | P12: =IF(COUNT($F12:$O12)=0,"",SUM($F12:$O12)) -> 223 | Q12: =IF(ISERROR(IF($P12="","",ROUND(($P12/$P$10)*$Q$10,2))),"",IF($P12="","",ROUND(($P12/$P$10)*$Q$10,2))) -> 76.9 | R12: =IF($Q12="","",ROUND($Q12*$R$10,2)) -> 46.14 | S12: =VLOOKUP(B12,'ET-1B'!D1:E20,2,FALSE) -> 18 | T12: =VLOOKUP(B12,'ET-1B'!D1:F20,3,FALSE) -> 18 | U12: =VLOOKUP(B12,'ET-1B'!D1:G20,4,FALSE) -> 18 | V12: =VLOOKUP(B12,'ET-1B'!D1:I20,6,FALSE) -> 18 | W12: =VLOOKUP(B12,'ET-1B'!D1:J20,7,FALSE) -> 13 | X12: =VLOOKUP(B12,'ET-1B'!D1:K20,8,FALSE) -> 18 | Y12: =VLOOKUP(B12,'ET-1B'!D1:L20,9,FALSE) -> 18 | Z12: =VLOOKUP(B12,'ET-1B'!D1:M20,10,FALSE) -> 20 | AA12: =VLOOKUP(B12,'ET-1B'!D1:O20,12,FALSE) -> 0 | AB12: =VLOOKUP(B12,'ET-1B'!D1:P20,13,FALSE) -> 18 | AC12: =IF(COUNT($S12:$AB12)=0,"",SUM($S12:$AB12)) -> 159 | AD12: =IF(ISERROR(IF($AC12="","",ROUND(($AC12/$AC$10)*$AD$10,2))),"",IF($AC12="","",ROUND(($AC12/$AC$10)*$AD$10,2))) -> 79.5 | AE12: =IF($AD12="","",ROUND($AD12*$AE$10,2)) -> 31.8 | AF12: 77 | AG12: =IF(ISERROR(IF($AF12="","",ROUND(($AF12/$AF$10)*$AG$10,2))),"",IF($AF12="","",ROUND(($AF12/$AF$10)*$AG$10,2))) -> 77 | AH12: =IF($AG12="","",ROUND($AG12*$AH$10,2)) -> 15.4 | AI12: =IF(ISERROR(IF($AF12="","",ROUND(SUM($R12,$AE12,$AH12),2))),"",IF($AF12="","",ROUND(SUM($R12,$AE12,$AH12),2))) -> 93.34 | AJ12: =IF(ISERROR(IF($AF12="","",VLOOKUP(AI12,TRANSMUTATION_TABLE,4,TRUE))),"",IF($AF12="","",VLOOKUP(AI12,TRANSMUTATION_TABLE,4,TRUE))) -> 95
A13: 2 | B13: Benitez, Joshua F. | F13: 34 | G13: 40 | H13: 29 | I13: 12 | J13: 34 | K13: 35 | L13: 30 | P13: =IF(COUNT($F13:$O13)=0,"",SUM($F13:$O13)) -> 214 | Q13: =IF(ISERROR(IF($P13="","",ROUND(($P13/$P$10)*$Q$10,2))),"",IF($P13="","",ROUND(($P13/$P$10)*$Q$10,2))) -> 73.79 | R13: =IF($Q13="","",ROUND($Q13*$R$10,2)) -> 44.27 | S13: =VLOOKUP(B13,'ET-1B'!D2:E21,2,FALSE) -> 18 | T13: =VLOOKUP(B13,'ET-1B'!D2:F21,3,FALSE) -> 18 | U13: =VLOOKUP(B13,'ET-1B'!D2:G21,4,FALSE) -> 18 | V13: =VLOOKUP(B13,'ET-1B'!D2:I21,6,FALSE) -> 20 | W13: =VLOOKUP(B13,'ET-1B'!D2:J21,7,FALSE) -> 20 | X13: =VLOOKUP(B13,'ET-1B'!D2:K21,8,FALSE) -> 18 | Y13: =VLOOKUP(B13,'ET-1B'!D2:L21,9,FALSE) -> 20 | Z13: =VLOOKUP(B13,'ET-1B'!D2:M21,10,FALSE) -> 20 | AA13: =VLOOKUP(B13,'ET-1B'!D2:O21,12,FALSE) -> 18 | AB13: =VLOOKUP(B13,'ET-1B'!D2:P21,13,FALSE) -> 20 | AC13: =IF(COUNT($S13:$AB13)=0,"",SUM($S13:$AB13)) -> 190 | AD13: =IF(ISERROR(IF($AC13="","",ROUND(($AC13/$AC$10)*$AD$10,2))),"",IF($AC13="","",ROUND(($AC13/$AC$10)*$AD$10,2))) -> 95 | AE13: =IF($AD13="","",ROUND($AD13*$AE$10,2)) -> 38 | AF13: 78 | AG13: =IF(ISERROR(IF($AF13="","",ROUND(($AF13/$AF$10)*$AG$10,2))),"",IF($AF13="","",ROUND(($AF13/$AF$10)*$AG$10,2))) -> 78 | AH13: =IF($AG13="","",ROUND($AG13*$AH$10,2)) -> 15.6 | AI13: =IF(ISERROR(IF($AF13="","",ROUND(SUM($R13,$AE13,$AH13),2))),"",IF($AF13="","",ROUND(SUM($R13,$AE13,$AH13),2))) -> 97.87 | AJ13: =IF(ISERROR(IF($AF13="","",VLOOKUP(AI13,TRANSMUTATION_TABLE,4,TRUE))),"",IF($AF13="","",VLOOKUP(AI13,TRANSMUTATION_TABLE,4,TRUE))) -> 98
A14: 3 | B14: Brillantes, Brent James | F14: 35 | G14: 41 | H14: 29 | I14: 29 | J14: 20 | K14: 36 | L14: 35 | P14: =IF(COUNT($F14:$O14)=0,"",SUM($F14:$O14)) -> 225 | Q14: =IF(ISERROR(IF($P14="","",ROUND(($P14/$P$10)*$Q$10,2))),"",IF($P14="","",ROUND(($P14/$P$10)*$Q$10,2))) -> 77.59 | R14: =IF($Q14="","",ROUND($Q14*$R$10,2)) -> 46.55 | S14: =VLOOKUP(B14,'ET-1B'!D3:E22,2,FALSE) -> #N/A | T14: =VLOOKUP(B14,'ET-1B'!D3:F22,3,FALSE) -> #N/A | U14: =VLOOKUP(B14,'ET-1B'!D3:G22,4,FALSE) -> #N/A | V14: =VLOOKUP(B14,'ET-1B'!D3:I22,6,FALSE) -> #N/A | W14: =VLOOKUP(B14,'ET-1B'!D3:J22,7,FALSE) -> #N/A | X14: =VLOOKUP(B14,'ET-1B'!D3:K22,8,FALSE) -> #N/A | Y14: =VLOOKUP(B14,'ET-1B'!D3:L22,9,FALSE) -> #N/A | Z14: =VLOOKUP(B14,'ET-1B'!D3:M22,10,FALSE) -> #N/A | AA14: =VLOOKUP(B14,'ET-1B'!D3:O22,12,FALSE) -> #N/A | AB14: =VLOOKUP(B14,'ET-1B'!D3:P22,13,FALSE) -> #N/A | AC14: =IF(COUNT($S14:$AB14)=0,"",SUM($S14:$AB14)) | AD14: =IF(ISERROR(IF($AC14="","",ROUND(($AC14/$AC$10)*$AD$10,2))),"",IF($AC14="","",ROUND(($AC14/$AC$10)*$AD$10,2))) | AE14: =IF($AD14="","",ROUND($AD14*$AE$10,2)) | AF14: 79 | AG14: =IF(ISERROR(IF($AF14="","",ROUND(($AF14/$AF$10)*$AG$10,2))),"",IF($AF14="","",ROUND(($AF14/$AF$10)*$AG$10,2))) -> 79 | AH14: =IF($AG14="","",ROUND($AG14*$AH$10,2)) -> 15.8 | AI14: =IF(ISERROR(IF($AF14="","",ROUND(SUM($R14,$AE14,$AH14),2))),"",IF($AF14="","",ROUND(SUM($R14,$AE14,$AH14),2))) -> 62.35 | AJ14: =IF(ISERROR(IF($AF14="","",VLOOKUP(AI14,TRANSMUTATION_TABLE,4,TRUE))),"",IF($AF14="","",VLOOKUP(AI14,TRANSMUTATION_TABLE,4,TRUE))) -> 76
A15: 4 | B15: Briñes, Jiro Miguel M. | F15: 36 | G15: 42 | H15: 23 | I15: 13 | J15: 35 | K15: 37 | L15: 35 | P15: =IF(COUNT($F15:$O15)=0,"",SUM($F15:$O15)) -> 221 | Q15: =IF(ISERROR(IF($P15="","",ROUND(($P15/$P$10)*$Q$10,2))),"",IF($P15="","",ROUND(($P15/$P$10)*$Q$10,2))) -> 76.21 | R15: =IF($Q15="","",ROUND($Q15*$R$10,2)) -> 45.73 | S15: =VLOOKUP(B15,'ET-1B'!D4:E23,2,FALSE) -> 18 | T15: =VLOOKUP(B15,'ET-1B'!D4:F23,3,FALSE) -> 18 | U15: =VLOOKUP(B15,'ET-1B'!D4:G23,4,FALSE) -> 18 | V15: =VLOOKUP(B15,'ET-1B'!D4:I23,6,FALSE) -> 20 | W15: =VLOOKUP(B15,'ET-1B'!D4:J23,7,FALSE) -> 20 | X15: =VLOOKUP(B15,'ET-1B'!D4:K23,8,FALSE) -> 18 | Y15: =VLOOKUP(B15,'ET-1B'!D4:L23,9,FALSE) -> 20 | Z15: =VLOOKUP(B15,'ET-1B'!D4:M23,10,FALSE) -> 20 | AA15: =VLOOKUP(B15,'ET-1B'!D4:O23,12,FALSE) -> 18 | AB15: =VLOOKUP(B15,'ET-1B'!D4:P23,13,FALSE) -> 20 | AC15: =IF(COUNT($S15:$AB15)=0,"",SUM($S15:$AB15)) -> 190 | AD15: =IF(ISERROR(IF($AC15="","",ROUND(($AC15/$AC$10)*$AD$10,2))),"",IF($AC15="","",ROUND(($AC15/$AC$10)*$AD$10,2))) -> 95 | AE15: =IF($AD15="","",ROUND($AD15*$AE$10,2)) -> 38 | AF15: 80 | AG15: =IF(ISERROR(IF($AF15="","",ROUND(($AF15/$AF$10)*$AG$10,2))),"",IF($AF15="","",ROUND(($AF15/$AF$10)*$AG$10,2))) -> 80 | AH15: =IF($AG15="","",ROUND($AG15*$AH$10,2)) -> 16 | AI15: =IF(ISERROR(IF($AF15="","",ROUND(SUM($R15,$AE15,$AH15),2))),"",IF($AF15="","",ROUND(SUM($R15,$AE15,$AH15),2))) -> 99.73 | AJ15: =IF(ISERROR(IF($AF15="","",VLOOKUP(AI15,TRANSMUTATION_TABLE,4,TRUE))),"",IF($AF15="","",VLOOKUP(AI15,TRANSMUTATION_TABLE,4,TRUE))) -> 99
A16: 5 | B16: Busante, Bryan Jerick | F16: 37 | G16: 43 | H16: 24 | I16: 18 | J16: 29 | K16: 38 | L16: 35 | P16: =IF(COUNT($F16:$O16)=0,"",SUM($F16:$O16)) -> 224 | Q16: =IF(ISERROR(IF($P16="","",ROUND(($P16/$P$10)*$Q$10,2))),"",IF($P16="","",ROUND(($P16/$P$10)*$Q$10,2))) -> 77.24 | R16: =IF($Q16="","",ROUND($Q16*$R$10,2)) -> 46.34 | S16: =VLOOKUP(B16,'ET-1B'!D5:E24,2,FALSE) -> 18 | T16: =VLOOKUP(B16,'ET-1B'!D5:F24,3,FALSE) -> 18 | U16: =VLOOKUP(B16,'ET-1B'!D5:G24,4,FALSE) -> 18 | V16: =VLOOKUP(B16,'ET-1B'!D5:I24,6,FALSE) -> 20 | W16: =VLOOKUP(B16,'ET-1B'!D5:J24,7,FALSE) -> 15 | X16: =VLOOKUP(B16,'ET-1B'!D5:K24,8,FALSE) -> 18 | Y16: =VLOOKUP(B16,'ET-1B'!D5:L24,9,FALSE) -> 20 | Z16: =VLOOKUP(B16,'ET-1B'!D5:M24,10,FALSE) -> 20 | AA16: =VLOOKUP(B16,'ET-1B'!D5:O24,12,FALSE) -> 18 | AB16: =VLOOKUP(B16,'ET-1B'!D5:P24,13,FALSE) -> 20 | AC16: =IF(COUNT($S16:$AB16)=0,"",SUM($S16:$AB16)) -> 185 | AD16: =IF(ISERROR(IF($AC16="","",ROUND(($AC16/$AC$10)*$AD$10,2))),"",IF($AC16="","",ROUND(($AC16/$AC$10)*$AD$10,2))) -> 92.5 | AE16: =IF($AD16="","",ROUND($AD16*$AE$10,2)) -> 37 | AF16: 81 | AG16: =IF(ISERROR(IF($AF16="","",ROUND(($AF16/$AF$10)*$AG$10,2))),"",IF($AF16="","",ROUND(($AF16/$AF$10)*$AG$10,2))) -> 81 | AH16: =IF($AG16="","",ROUND($AG16*$AH$10,2)) -> 16.2 | AI16: =IF(ISERROR(IF($AF16="","",ROUND(SUM($R16,$AE16,$AH16),2))),"",IF($AF16="","",ROUND(SUM($R16,$AE16,$AH16),2))) -> 99.54 | AJ16: =IF(ISERROR(IF($AF16="","",VLOOKUP(AI16,TRANSMUTATION_TABLE,4,TRUE))),"",IF($AF16="","",VLOOKUP(AI16,TRANSMUTATION_TABLE,4,TRUE))) -> 99
A17: 6 | B17: Canamales, Joshua C. | F17: 38 | G17: 44 | H17: 25 | I17: 17 | J17: 28 | K17: 39 | L17: 35 | P17: =IF(COUNT($F17:$O17)=0,"",SUM($F17:$O17)) -> 226 | Q17: =IF(ISERROR(IF($P17="","",ROUND(($P17/$P$10)*$Q$10,2))),"",IF($P17="","",ROUND(($P17/$P$10)*$Q$10,2))) -> 77.93 | R17: =IF($Q17="","",ROUND($Q17*$R$10,2)) -> 46.76 | S17: =VLOOKUP(B17,'ET-1B'!D6:E25,2,FALSE) -> #N/A | T17: =VLOOKUP(B17,'ET-1B'!D6:F25,3,FALSE) -> #N/A | U17: =VLOOKUP(B17,'ET-1B'!D6:G25,4,FALSE) -> #N/A | V17: =VLOOKUP(B17,'ET-1B'!D6:I25,6,FALSE) -> #N/A | W17: =VLOOKUP(B17,'ET-1B'!D6:J25,7,FALSE) -> #N/A | X17: =VLOOKUP(B17,'ET-1B'!D6:K25,8,FALSE) -> #N/A | Y17: =VLOOKUP(B17,'ET-1B'!D6:L25,9,FALSE) -> #N/A | Z17: =VLOOKUP(B17,'ET-1B'!D6:M25,10,FALSE) -> #N/A | AA17: =VLOOKUP(B17,'ET-1B'!D6:O25,12,FALSE) -> #N/A | AB17: =VLOOKUP(B17,'ET-1B'!D6:P25,13,FALSE) -> #N/A | AC17: =IF(COUNT($S17:$AB17)=0,"",SUM($S17:$AB17)) | AD17: =IF(ISERROR(IF($AC17="","",ROUND(($AC17/$AC$10)*$AD$10,2))),"",IF($AC17="","",ROUND(($AC17/$AC$10)*$AD$10,2))) | AE17: =IF($AD17="","",ROUND($AD17*$AE$10,2)) | AF17: 82 | AG17: =IF(ISERROR(IF($AF17="","",ROUND(($AF17/$AF$10)*$AG$10,2))),"",IF($AF17="","",ROUND(($AF17/$AF$10)*$AG$10,2))) -> 82 | AH17: =IF($AG17="","",ROUND($AG17*$AH$10,2)) -> 16.4 | AI17: =IF(ISERROR(IF($AF17="","",ROUND(SUM($R17,$AE17,$AH17),2))),"",IF($AF17="","",ROUND(SUM($R17,$AE17,$AH17),2))) -> 63.16 | AJ17: =IF(ISERROR(IF($AF17="","",VLOOKUP(AI17,TRANSMUTATION_TABLE,4,TRUE))),"",IF($AF17="","",VLOOKUP(AI17,TRANSMUTATION_TABLE,4,TRUE))) -> 76
A18: 7 | B18: Contaoi, Marl Cedric | F18: 39 | G18: 45 | H18: 26 | I18: 16 | J18: 27 | K18: 40 | L18: 35 | P18: =IF(COUNT($F18:$O18)=0,"",SUM($F18:$O18)) -> 228 | Q18: =IF(ISERROR(IF($P18="","",ROUND(($P18/$P$10)*$Q$10,2))),"",IF($P18="","",ROUND(($P18/$P$10)*$Q$10,2))) -> 78.62 | R18: =IF($Q18="","",ROUND($Q18*$R$10,2)) -> 47.17 | S18: =VLOOKUP(B18,'ET-1B'!D7:E26,2,FALSE) -> #N/A | T18: =VLOOKUP(B18,'ET-1B'!D7:F26,3,FALSE) -> #N/A | U18: =VLOOKUP(B18,'ET-1B'!D7:G26,4,FALSE) -> #N/A | V18: =VLOOKUP(B18,'ET-1B'!D7:I26,6,FALSE) -> #N/A | W18: =VLOOKUP(B18,'ET-1B'!D7:J26,7,FALSE) -> #N/A | X18: =VLOOKUP(B18,'ET-1B'!D7:K26,8,FALSE) -> #N/A | Y18: =VLOOKUP(B18,'ET-1B'!D7:L26,9,FALSE) -> #N/A | Z18: =VLOOKUP(B18,'ET-1B'!D7:M26,10,FALSE) -> #N/A | AA18: =VLOOKUP(B18,'ET-1B'!D7:O26,12,FALSE) -> #N/A | AB18: =VLOOKUP(B18,'ET-1B'!D7:P26,13,FALSE) -> #N/A | AC18: =IF(COUNT($S18:$AB18)=0,"",SUM($S18:$AB18)) | AD18: =IF(ISERROR(IF($AC18="","",ROUND(($AC18/$AC$10)*$AD$10,2))),"",IF($AC18="","",ROUND(($AC18/$AC$10)*$AD$10,2))) | AE18: =IF($AD18="","",ROUND($AD18*$AE$10,2)) | AF18: 83 | AG18: =IF(ISERROR(IF($AF18="","",ROUND(($AF18/$AF$10)*$AG$10,2))),"",IF($AF18="","",ROUND(($AF18/$AF$10)*$AG$10,2))) -> 83 | AH18: =IF($AG18="","",ROUND($AG18*$AH$10,2)) -> 16.6 | AI18: =IF(ISERROR(IF($AF18="","",ROUND(SUM($R18,$AE18,$AH18),2))),"",IF($AF18="","",ROUND(SUM($R18,$AE18,$AH18),2))) -> 63.77 | AJ18: =IF(ISERROR(IF($AF18="","",VLOOKUP(AI18,TRANSMUTATION_TABLE,4,TRUE))),"",IF($AF18="","",VLOOKUP(AI18,TRANSMUTATION_TABLE,4,TRUE))) -> 77
A19: 8 | B19: Diestro, Daniel M. | F19: 40 | G19: 46 | H19: 27 | I19: 13 | J19: 26 | K19: 41 | L19: 31 | P19: =IF(COUNT($F19:$O19)=0,"",SUM($F19:$O19)) -> 224 | Q19: =IF(ISERROR(IF($P19="","",ROUND(($P19/$P$10)*$Q$10,2))),"",IF($P19="","",ROUND(($P19/$P$10)*$Q$10,2))) -> 77.24 | R19: =IF($Q19="","",ROUND($Q19*$R$10,2)) -> 46.34 | S19: =VLOOKUP(B19,'ET-1B'!D8:E27,2,FALSE) -> 18 | T19: =VLOOKUP(B19,'ET-1B'!D8:F27,3,FALSE) -> 18 | U19: =VLOOKUP(B19,'ET-1B'!D8:G27,4,FALSE) -> 18 | V19: =VLOOKUP(B19,'ET-1B'!D8:I27,6,FALSE) -> 20 | W19: =VLOOKUP(B19,'ET-1B'!D8:J27,7,FALSE) -> 20 | X19: =VLOOKUP(B19,'ET-1B'!D8:K27,8,FALSE) -> 18 | Y19: =VLOOKUP(B19,'ET-1B'!D8:L27,9,FALSE) -> 20 | Z19: =VLOOKUP(B19,'ET-1B'!D8:M27,10,FALSE) -> 20 | AA19: =VLOOKUP(B19,'ET-1B'!D8:O27,12,FALSE) -> 18 | AB19: =VLOOKUP(B19,'ET-1B'!D8:P27,13,FALSE) -> 0 | AC19: =IF(COUNT($S19:$AB19)=0,"",SUM($S19:$AB19)) -> 170 | AD19: =IF(ISERROR(IF($AC19="","",ROUND(($AC19/$AC$10)*$AD$10,2))),"",IF($AC19="","",ROUND(($AC19/$AC$10)*$AD$10,2))) -> 85 | AE19: =IF($AD19="","",ROUND($AD19*$AE$10,2)) -> 34 | AF19: 84 | AG19: =IF(ISERROR(IF($AF19="","",ROUND(($AF19/$AF$10)*$AG$10,2))),"",IF($AF19="","",ROUND(($AF19/$AF$10)*$AG$10,2))) -> 84 | AH19: =IF($AG19="","",ROUND($AG19*$AH$10,2)) -> 16.8 | AI19: =IF(ISERROR(IF($AF19="","",ROUND(SUM($R19,$AE19,$AH19),2))),"",IF($AF19="","",ROUND(SUM($R19,$AE19,$AH19),2))) -> 97.14 | AJ19: =IF(ISERROR(IF($AF19="","",VLOOKUP(AI19,TRANSMUTATION_TABLE,4,TRUE))),"",IF($AF19="","",VLOOKUP(AI19,TRANSMUTATION_TABLE,4,TRUE))) -> 98
A20: 9 | B20: Egca, Benedict D. | D20: 0 | F20: 41 | G20: 47 | H20: 28 | I20: 14 | J20: 25 | K20: 42 | L20: 28 | P20: =IF(COUNT($F20:$O20)=0,"",SUM($F20:$O20)) -> 225 | Q20: =IF(ISERROR(IF($P20="","",ROUND(($P20/$P$10)*$Q$10,2))),"",IF($P20="","",ROUND(($P20/$P$10)*$Q$10,2))) -> 77.59 | R20: =IF($Q20="","",ROUND($Q20*$R$10,2)) -> 46.55 | S20: =VLOOKUP(B20,'ET-1B'!D9:E28,2,FALSE) -> #N/A | T20: =VLOOKUP(B20,'ET-1B'!D9:F28,3,FALSE) -> #N/A | U20: =VLOOKUP(B20,'ET-1B'!D9:G28,4,FALSE) -> #N/A | V20: =VLOOKUP(B20,'ET-1B'!D9:I28,6,FALSE) -> #N/A | W20: =VLOOKUP(B20,'ET-1B'!D9:J28,7,FALSE) -> #N/A | X20: =VLOOKUP(B20,'ET-1B'!D9:K28,8,FALSE) -> #N/A | Y20: =VLOOKUP(B20,'ET-1B'!D9:L28,9,FALSE) -> #N/A | Z20: =VLOOKUP(B20,'ET-1B'!D9:M28,10,FALSE) -> #N/A | AA20: =VLOOKUP(B20,'ET-1B'!D9:O28,12,FALSE) -> #N/A | AB20: =VLOOKUP(B20,'ET-1B'!D9:P28,13,FALSE) -> #N/A | AC20: =IF(COUNT($S20:$AB20)=0,"",SUM($S20:$AB20)) | AD20: =IF(ISERROR(IF($AC20="","",ROUND(($AC20/$AC$10)*$AD$10,2))),"",IF($AC20="","",ROUND(($AC20/$AC$10)*$AD$10,2))) | AE20: =IF($AD20="","",ROUND($AD20*$AE$10,2)) | AF20: 85 | AG20: =IF(ISERROR(IF($AF20="","",ROUND(($AF20/$AF$10)*$AG$10,2))),"",IF($AF20="","",ROUND(($AF20/$AF$10)*$AG$10,2))) -> 85 | AH20: =IF($AG20="","",ROUND($AG20*$AH$10,2)) -> 17 | AI20: =IF(ISERROR(IF($AF20="","",ROUND(SUM($R20,$AE20,$AH20),2))),"",IF($AF20="","",ROUND(SUM($R20,$AE20,$AH20),2))) -> 63.55 | AJ20: =IF(ISERROR(IF($AF20="","",VLOOKUP(AI20,TRANSMUTATION_TABLE,4,TRUE))),"",IF($AF20="","",VLOOKUP(AI20,TRANSMUTATION_TABLE,4,TRUE))) -> 77
A21: 10 | B21: Estil, Jester A. | F21: 42 | G21: 48 | H21: 29 | I21: 15 | J21: 29 | K21: 43 | L21: 24 | P21: =IF(COUNT($F21:$O21)=0,"",SUM($F21:$O21)) -> 230 | Q21: =IF(ISERROR(IF($P21="","",ROUND(($P21/$P$10)*$Q$10,2))),"",IF($P21="","",ROUND(($P21/$P$10)*$Q$10,2))) -> 79.31 | R21: =IF($Q21="","",ROUND($Q21*$R$10,2)) -> 47.59 | S21: =VLOOKUP(B21,'ET-1B'!D10:E29,2,FALSE) -> #N/A | T21: =VLOOKUP(B21,'ET-1B'!D10:F29,3,FALSE) -> #N/A | U21: =VLOOKUP(B21,'ET-1B'!D10:G29,4,FALSE) -> #N/A | V21: =VLOOKUP(B21,'ET-1B'!D10:I29,6,FALSE) -> #N/A | W21: =VLOOKUP(B21,'ET-1B'!D10:J29,7,FALSE) -> #N/A | X21: =VLOOKUP(B21,'ET-1B'!D10:K29,8,FALSE) -> #N/A | Y21: =VLOOKUP(B21,'ET-1B'!D10:L29,9,FALSE) -> #N/A | Z21: =VLOOKUP(B21,'ET-1B'!D10:M29,10,FALSE) -> #N/A | AA21: =VLOOKUP(B21,'ET-1B'!D10:O29,12,FALSE) -> #N/A | AB21: =VLOOKUP(B21,'ET-1B'!D10:P29,13,FALSE) -> #N/A | AC21: =IF(COUNT($S21:$AB21)=0,"",SUM($S21:$AB21)) | AD21: =IF(ISERROR(IF($AC21="","",ROUND(($AC21/$AC$10)*$AD$10,2))),"",IF($AC21="","",ROUND(($AC21/$AC$10)*$AD$10,2))) | AE21: =IF($AD21="","",ROUND($AD21*$AE$10,2)) | AF21: 86 | AG21: =IF(ISERROR(IF($AF21="","",ROUND(($AF21/$AF$10)*$AG$10,2))),"",IF($AF21="","",ROUND(($AF21/$AF$10)*$AG$10,2))) -> 86 | AH21: =IF($AG21="","",ROUND($AG21*$AH$10,2)) -> 17.2 | AI21: =IF(ISERROR(IF($AF21="","",ROUND(SUM($R21,$AE21,$AH21),2))),"",IF($AF21="","",ROUND(SUM($R21,$AE21,$AH21),2))) -> 64.79 | AJ21: =IF(ISERROR(IF($AF21="","",VLOOKUP(AI21,TRANSMUTATION_TABLE,4,TRUE))),"",IF($AF21="","",VLOOKUP(AI21,TRANSMUTATION_TABLE,4,TRUE))) -> 77
A22: 11 | B22: Eugenio, Kirk Benedict O. | F22: 43 | G22: 49 | H22: 30 | I22: 23 | J22: 28 | K22: 30 | L22: 28 | P22: =IF(COUNT($F22:$O22)=0,"",SUM($F22:$O22)) -> 231 | Q22: =IF(ISERROR(IF($P22="","",ROUND(($P22/$P$10)*$Q$10,2))),"",IF($P22="","",ROUND(($P22/$P$10)*$Q$10,2))) -> 79.66 | R22: =IF($Q22="","",ROUND($Q22*$R$10,2)) -> 47.8 | S22: =VLOOKUP(B22,'ET-1B'!D11:E30,2,FALSE) -> 0 | T22: =VLOOKUP(B22,'ET-1B'!D11:F30,3,FALSE) -> 18 | U22: =VLOOKUP(B22,'ET-1B'!D11:G30,4,FALSE) -> 18 | V22: =VLOOKUP(B22,'ET-1B'!D11:I30,6,FALSE) -> 18 | W22: =VLOOKUP(B22,'ET-1B'!D11:J30,7,FALSE) -> 20 | X22: =VLOOKUP(B22,'ET-1B'!D11:K30,8,FALSE) -> 18 | Y22: =VLOOKUP(B22,'ET-1B'!D11:L30,9,FALSE) -> 0 | Z22: =VLOOKUP(B22,'ET-1B'!D11:M30,10,FALSE) -> 13 | AA22: =VLOOKUP(B22,'ET-1B'!D11:O30,12,FALSE) -> 18 | AB22: =VLOOKUP(B22,'ET-1B'!D11:P30,13,FALSE) -> 0 | AC22: =IF(COUNT($S22:$AB22)=0,"",SUM($S22:$AB22)) -> 123 | AD22: =IF(ISERROR(IF($AC22="","",ROUND(($AC22/$AC$10)*$AD$10,2))),"",IF($AC22="","",ROUND(($AC22/$AC$10)*$AD$10,2))) -> 61.5 | AE22: =IF($AD22="","",ROUND($AD22*$AE$10,2)) -> 24.6 | AF22: 87 | AG22: =IF(ISERROR(IF($AF22="","",ROUND(($AF22/$AF$10)*$AG$10,2))),"",IF($AF22="","",ROUND(($AF22/$AF$10)*$AG$10,2))) -> 87 | AH22: =IF($AG22="","",ROUND($AG22*$AH$10,2)) -> 17.4 | AI22: =IF(ISERROR(IF($AF22="","",ROUND(SUM($R22,$AE22,$AH22),2))),"",IF($AF22="","",ROUND(SUM($R22,$AE22,$AH22),2))) -> 89.8 | AJ22: =IF(ISERROR(IF($AF22="","",VLOOKUP(AI22,TRANSMUTATION_TABLE,4,TRUE))),"",IF($AF22="","",VLOOKUP(AI22,TRANSMUTATION_TABLE,4,TRUE))) -> 93
A23: 12 | B23: Francisco, Reign T. | D23: 0 | F23: 44 | G23: 39 | H23: 30 | I23: 24 | J23: 27 | K23: 30 | L23: 25 | P23: =IF(COUNT($F23:$O23)=0,"",SUM($F23:$O23)) -> 219 | Q23: =IF(ISERROR(IF($P23="","",ROUND(($P23/$P$10)*$Q$10,2))),"",IF($P23="","",ROUND(($P23/$P$10)*$Q$10,2))) -> 75.52 | R23: =IF($Q23="","",ROUND($Q23*$R$10,2)) -> 45.31 | S23: =VLOOKUP(B23,'ET-1B'!D12:E31,2,FALSE) -> 18 | T23: =VLOOKUP(B23,'ET-1B'!D12:F31,3,FALSE) -> 18 | U23: =VLOOKUP(B23,'ET-1B'!D12:G31,4,FALSE) -> 18 | V23: =VLOOKUP(B23,'ET-1B'!D12:I31,6,FALSE) -> 20 | W23: =VLOOKUP(B23,'ET-1B'!D12:J31,7,FALSE) -> 18 | X23: =VLOOKUP(B23,'ET-1B'!D12:K31,8,FALSE) -> 18 | Y23: =VLOOKUP(B23,'ET-1B'!D12:L31,9,FALSE) -> 18 | Z23: =VLOOKUP(B23,'ET-1B'!D12:M31,10,FALSE) -> 13 | AA23: =VLOOKUP(B23,'ET-1B'!D12:O31,12,FALSE) -> 18 | AB23: =VLOOKUP(B23,'ET-1B'!D12:P31,13,FALSE) -> 0 | AC23: =IF(COUNT($S23:$AB23)=0,"",SUM($S23:$AB23)) -> 159 | AD23: =IF(ISERROR(IF($AC23="","",ROUND(($AC23/$AC$10)*$AD$10,2))),"",IF($AC23="","",ROUND(($AC23/$AC$10)*$AD$10,2))) -> 79.5 | AE23: =IF($AD23="","",ROUND($AD23*$AE$10,2)) -> 31.8 | AF23: 88 | AG23: =IF(ISERROR(IF($AF23="","",ROUND(($AF23/$AF$10)*$AG$10,2))),"",IF($AF23="","",ROUND(($AF23/$AF$10)*$AG$10,2))) -> 88 | AH23: =IF($AG23="","",ROUND($AG23*$AH$10,2)) -> 17.6 | AI23: =IF(ISERROR(IF($AF23="","",ROUND(SUM($R23,$AE23,$AH23),2))),"",IF($AF23="","",ROUND(SUM($R23,$AE23,$AH23),2))) -> 94.71 | AJ23: =IF(ISERROR(IF($AF23="","",VLOOKUP(AI23,TRANSMUTATION_TABLE,4,TRUE))),"",IF($AF23="","",VLOOKUP(AI23,TRANSMUTATION_TABLE,4,TRUE))) -> 96
A24: 13 | B24: Herrera, Rednash T. | F24: 45 | G24: 41 | H24: 30 | I24: 25 | J24: 24 | K24: 31 | L24: 27 | P24: =IF(COUNT($F24:$O24)=0,"",SUM($F24:$O24)) -> 223 | Q24: =IF(ISERROR(IF($P24="","",ROUND(($P24/$P$10)*$Q$10,2))),"",IF($P24="","",ROUND(($P24/$P$10)*$Q$10,2))) -> 76.9 | R24: =IF($Q24="","",ROUND($Q24*$R$10,2)) -> 46.14 | S24: =VLOOKUP(B24,'ET-1B'!D13:E32,2,FALSE) -> 18 | T24: =VLOOKUP(B24,'ET-1B'!D13:F32,3,FALSE) -> 18 | U24: =VLOOKUP(B24,'ET-1B'!D13:G32,4,FALSE) -> 18 | V24: =VLOOKUP(B24,'ET-1B'!D13:I32,6,FALSE) -> 15 | W24: =VLOOKUP(B24,'ET-1B'!D13:J32,7,FALSE) -> 20 | X24: =VLOOKUP(B24,'ET-1B'!D13:K32,8,FALSE) -> 18 | Y24: =VLOOKUP(B24,'ET-1B'!D13:L32,9,FALSE) -> 0 | Z24: =VLOOKUP(B24,'ET-1B'!D13:M32,10,FALSE) -> 20 | AA24: =VLOOKUP(B24,'ET-1B'!D13:O32,12,FALSE) -> 18 | AB24: =VLOOKUP(B24,'ET-1B'!D13:P32,13,FALSE) -> 0 | AC24: =IF(COUNT($S24:$AB24)=0,"",SUM($S24:$AB24)) -> 145 | AD24: =IF(ISERROR(IF($AC24="","",ROUND(($AC24/$AC$10)*$AD$10,2))),"",IF($AC24="","",ROUND(($AC24/$AC$10)*$AD$10,2))) -> 72.5 | AE24: =IF($AD24="","",ROUND($AD24*$AE$10,2)) -> 29 | AF24: 89 | AG24: =IF(ISERROR(IF($AF24="","",ROUND(($AF24/$AF$10)*$AG$10,2))),"",IF($AF24="","",ROUND(($AF24/$AF$10)*$AG$10,2))) -> 89 | AH24: =IF($AG24="","",ROUND($AG24*$AH$10,2)) -> 17.8 | AI24: =IF(ISERROR(IF($AF24="","",ROUND(SUM($R24,$AE24,$AH24),2))),"",IF($AF24="","",ROUND(SUM($R24,$AE24,$AH24),2))) -> 92.94 | AJ24: =IF(ISERROR(IF($AF24="","",VLOOKUP(AI24,TRANSMUTATION_TABLE,4,TRUE))),"",IF($AF24="","",VLOOKUP(AI24,TRANSMUTATION_TABLE,4,TRUE))) -> 95
A25: 14 | B25: Limosnero, Frankie A. | F25: 46 | G25: 46 | H25: 30 | I25: 26 | J25: 21 | K25: 20 | L25: 26 | P25: =IF(COUNT($F25:$O25)=0,"",SUM($F25:$O25)) -> 215 | Q25: =IF(ISERROR(IF($P25="","",ROUND(($P25/$P$10)*$Q$10,2))),"",IF($P25="","",ROUND(($P25/$P$10)*$Q$10,2))) -> 74.14 | R25: =IF($Q25="","",ROUND($Q25*$R$10,2)) -> 44.48 | S25: =VLOOKUP(B25,'ET-1B'!D14:E33,2,FALSE) -> #N/A | T25: =VLOOKUP(B25,'ET-1B'!D14:F33,3,FALSE) -> #N/A | U25: =VLOOKUP(B25,'ET-1B'!D14:G33,4,FALSE) -> #N/A | V25: =VLOOKUP(B25,'ET-1B'!D14:I33,6,FALSE) -> #N/A | W25: =VLOOKUP(B25,'ET-1B'!D14:J33,7,FALSE) -> #N/A | X25: =VLOOKUP(B25,'ET-1B'!D14:K33,8,FALSE) -> #N/A | Y25: =VLOOKUP(B25,'ET-1B'!D14:L33,9,FALSE) -> #N/A | Z25: =VLOOKUP(B25,'ET-1B'!D14:M33,10,FALSE) -> #N/A | AA25: =VLOOKUP(B25,'ET-1B'!D14:O33,12,FALSE) -> #N/A | AB25: =VLOOKUP(B25,'ET-1B'!D14:P33,13,FALSE) -> #N/A | AC25: =IF(COUNT($S25:$AB25)=0,"",SUM($S25:$AB25)) | AD25: =IF(ISERROR(IF($AC25="","",ROUND(($AC25/$AC$10)*$AD$10,2))),"",IF($AC25="","",ROUND(($AC25/$AC$10)*$AD$10,2))) | AE25: =IF($AD25="","",ROUND($AD25*$AE$10,2)) | AF25: 91 | AG25: =IF(ISERROR(IF($AF25="","",ROUND(($AF25/$AF$10)*$AG$10,2))),"",IF($AF25="","",ROUND(($AF25/$AF$10)*$AG$10,2))) -> 91 | AH25: =IF($AG25="","",ROUND($AG25*$AH$10,2)) -> 18.2 | AI25: =IF(ISERROR(IF($AF25="","",ROUND(SUM($R25,$AE25,$AH25),2))),"",IF($AF25="","",ROUND(SUM($R25,$AE25,$AH25),2))) -> 62.68 | AJ25: =IF(ISERROR(IF($AF25="","",VLOOKUP(AI25,TRANSMUTATION_TABLE,4,TRUE))),"",IF($AF25="","",VLOOKUP(AI25,TRANSMUTATION_TABLE,4,TRUE))) -> 76
A26: 15 | B26: Mater, Aron M. | F26: 47 | G26: 38 | H26: 29 | I26: 27 | J26: 20 | K26: 21 | L26: 28 | P26: =IF(COUNT($F26:$O26)=0,"",SUM($F26:$O26)) -> 210 | Q26: =IF(ISERROR(IF($P26="","",ROUND(($P26/$P$10)*$Q$10,2))),"",IF($P26="","",ROUND(($P26/$P$10)*$Q$10,2))) -> 72.41 | R26: =IF($Q26="","",ROUND($Q26*$R$10,2)) -> 43.45 | S26: =VLOOKUP(B26,'ET-1B'!D15:E34,2,FALSE) -> #N/A | T26: =VLOOKUP(B26,'ET-1B'!D15:F34,3,FALSE) -> #N/A | U26: =VLOOKUP(B26,'ET-1B'!D15:G34,4,FALSE) -> #N/A | V26: =VLOOKUP(B26,'ET-1B'!D15:I34,6,FALSE) -> #N/A | W26: =VLOOKUP(B26,'ET-1B'!D15:J34,7,FALSE) -> #N/A | X26: =VLOOKUP(B26,'ET-1B'!D15:K34,8,FALSE) -> #N/A | Y26: =VLOOKUP(B26,'ET-1B'!D15:L34,9,FALSE) -> #N/A | Z26: =VLOOKUP(B26,'ET-1B'!D15:M34,10,FALSE) -> #N/A | AA26: =VLOOKUP(B26,'ET-1B'!D15:O34,12,FALSE) -> #N/A | AB26: =VLOOKUP(B26,'ET-1B'!D15:P34,13,FALSE) -> #N/A | AC26: =IF(COUNT($S26:$AB26)=0,"",SUM($S26:$AB26)) | AD26: =IF(ISERROR(IF($AC26="","",ROUND(($AC26/$AC$10)*$AD$10,2))),"",IF($AC26="","",ROUND(($AC26/$AC$10)*$AD$10,2))) | AE26: =IF($AD26="","",ROUND($AD26*$AE$10,2)) | AF26: 91 | AG26: =IF(ISERROR(IF($AF26="","",ROUND(($AF26/$AF$10)*$AG$10,2))),"",IF($AF26="","",ROUND(($AF26/$AF$10)*$AG$10,2))) -> 91 | AH26: =IF($AG26="","",ROUND($AG26*$AH$10,2)) -> 18.2 | AI26: =IF(ISERROR(IF($AF26="","",ROUND(SUM($R26,$AE26,$AH26),2))),"",IF($AF26="","",ROUND(SUM($R26,$AE26,$AH26),2))) -> 61.65 | AJ26: =IF(ISERROR(IF($AF26="","",VLOOKUP(AI26,TRANSMUTATION_TABLE,4,TRUE))),"",IF($AF26="","",VLOOKUP(AI26,TRANSMUTATION_TABLE,4,TRUE))) -> 76
A27: 16 | B27: Matuguina, Rhamil C. | F27: 48 | G27: 39 | H27: 28 | I27: 28 | J27: 20 | K27: 30 | L27: 29 | P27: =IF(COUNT($F27:$O27)=0,"",SUM($F27:$O27)) -> 222 | Q27: =IF(ISERROR(IF($P27="","",ROUND(($P27/$P$10)*$Q$10,2))),"",IF($P27="","",ROUND(($P27/$P$10)*$Q$10,2))) -> 76.55 | R27: =IF($Q27="","",ROUND($Q27*$R$10,2)) -> 45.93 | S27: =VLOOKUP(B27,'ET-1B'!D16:E35,2,FALSE) -> #N/A | T27: =VLOOKUP(B27,'ET-1B'!D16:F35,3,FALSE) -> #N/A | U27: =VLOOKUP(B27,'ET-1B'!D16:G35,4,FALSE) -> #N/A | V27: =VLOOKUP(B27,'ET-1B'!D16:I35,6,FALSE) -> #N/A | W27: =VLOOKUP(B27,'ET-1B'!D16:J35,7,FALSE) -> #N/A | X27: =VLOOKUP(B27,'ET-1B'!D16:K35,8,FALSE) -> #N/A | Y27: =VLOOKUP(B27,'ET-1B'!D16:L35,9,FALSE) -> #N/A | Z27: =VLOOKUP(B27,'ET-1B'!D16:M35,10,FALSE) -> #N/A | AA27: =VLOOKUP(B27,'ET-1B'!D16:O35,12,FALSE) -> #N/A | AB27: =VLOOKUP(B27,'ET-1B'!D16:P35,13,FALSE) -> #N/A | AC27: =IF(COUNT($S27:$AB27)=0,"",SUM($S27:$AB27)) | AD27: =IF(ISERROR(IF($AC27="","",ROUND(($AC27/$AC$10)*$AD$10,2))),"",IF($AC27="","",ROUND(($AC27/$AC$10)*$AD$10,2))) | AE27: =IF($AD27="","",ROUND($AD27*$AE$10,2)) | AF27: 92 | AG27: =IF(ISERROR(IF($AF27="","",ROUND(($AF27/$AF$10)*$AG$10,2))),"",IF($AF27="","",ROUND(($AF27/$AF$10)*$AG$10,2))) -> 92 | AH27: =IF($AG27="","",ROUND($AG27*$AH$10,2)) -> 18.4 | AI27: =IF(ISERROR(IF($AF27="","",ROUND(SUM($R27,$AE27,$AH27),2))),"",IF($AF27="","",ROUND(SUM($R27,$AE27,$AH27),2))) -> 64.33 | AJ27: =IF(ISERROR(IF($AF27="","",VLOOKUP(AI27,TRANSMUTATION_TABLE,4,TRUE))),"",IF($AF27="","",VLOOKUP(AI27,TRANSMUTATION_TABLE,4,TRUE))) -> 77
A28: 17 | B28: Perina, Gerryko Geollegue | F28: 29 | G28: 30 | H28: 29 | I28: 23 | J28: 26 | K28: 35 | L28: 34 | P28: =IF(COUNT($F28:$O28)=0,"",SUM($F28:$O28)) -> 206 | Q28: =IF(ISERROR(IF($P28="","",ROUND(($P28/$P$10)*$Q$10,2))),"",IF($P28="","",ROUND(($P28/$P$10)*$Q$10,2))) -> 71.03 | R28: =IF($Q28="","",ROUND($Q28*$R$10,2)) -> 42.62 | S28: =VLOOKUP(B28,'ET-1B'!D17:E36,2,FALSE) -> #N/A | T28: =VLOOKUP(B28,'ET-1B'!D17:F36,3,FALSE) -> #N/A | U28: =VLOOKUP(B28,'ET-1B'!D17:G36,4,FALSE) -> #N/A | V28: =VLOOKUP(B28,'ET-1B'!D17:I36,6,FALSE) -> #N/A | W28: =VLOOKUP(B28,'ET-1B'!D17:J36,7,FALSE) -> #N/A | X28: =VLOOKUP(B28,'ET-1B'!D17:K36,8,FALSE) -> #N/A | Y28: =VLOOKUP(B28,'ET-1B'!D17:L36,9,FALSE) -> #N/A | Z28: =VLOOKUP(B28,'ET-1B'!D17:M36,10,FALSE) -> #N/A | AA28: =VLOOKUP(B28,'ET-1B'!D17:O36,12,FALSE) -> #N/A | AB28: =VLOOKUP(B28,'ET-1B'!D17:P36,13,FALSE) -> #N/A | AC28: =IF(COUNT($S28:$AB28)=0,"",SUM($S28:$AB28)) | AD28: =IF(ISERROR(IF($AC28="","",ROUND(($AC28/$AC$10)*$AD$10,2))),"",IF($AC28="","",ROUND(($AC28/$AC$10)*$AD$10,2))) | AE28: =IF($AD28="","",ROUND($AD28*$AE$10,2)) | AF28: 93 | AG28: =IF(ISERROR(IF($AF28="","",ROUND(($AF28/$AF$10)*$AG$10,2))),"",IF($AF28="","",ROUND(($AF28/$AF$10)*$AG$10,2))) -> 93 | AH28: =IF($AG28="","",ROUND($AG28*$AH$10,2)) -> 18.6 | AI28: =IF(ISERROR(IF($AF28="","",ROUND(SUM($R28,$AE28,$AH28),2))),"",IF($AF28="","",ROUND(SUM($R28,$AE28,$AH28),2))) -> 61.22 | AJ28: =IF(ISERROR(IF($AF28="","",VLOOKUP(AI28,TRANSMUTATION_TABLE,4,TRUE))),"",IF($AF28="","",VLOOKUP(AI28,TRANSMUTATION_TABLE,4,TRUE))) -> 75
A29: 18 | B29: Reyes, Daniell Joseph F. | F29: 41 | G29: 39 | H29: 27 | I29: 16 | J29: 32 | K29: 30 | L29: 30 | P29: =IF(COUNT($F29:$O29)=0,"",SUM($F29:$O29)) -> 215 | Q29: =IF(ISERROR(IF($P29="","",ROUND(($P29/$P$10)*$Q$10,2))),"",IF($P29="","",ROUND(($P29/$P$10)*$Q$10,2))) -> 74.14 | R29: =IF($Q29="","",ROUND($Q29*$R$10,2)) -> 44.48 | S29: =VLOOKUP(B29,'ET-1B'!D1:E20,2,FALSE) -> 18 | T29: =VLOOKUP(B29,'ET-1B'!D1:F20,3,FALSE) -> 18 | U29: =VLOOKUP(B29,'ET-1B'!D1:G20,4,FALSE) -> 18 | V29: =VLOOKUP(B29,'ET-1B'!D1:I20,6,FALSE) -> 18 | W29: =VLOOKUP(B29,'ET-1B'!D1:J20,7,FALSE) -> 18 | X29: =VLOOKUP(B29,'ET-1B'!D1:K20,8,FALSE) -> 18 | Y29: =VLOOKUP(B29,'ET-1B'!D1:L20,9,FALSE) -> 18 | Z29: =-VLOOKUP(B29,'ET-1B'!D1:M20,10,FALSE) -> 0 | AA29: =VLOOKUP(B29,'ET-1B'!D1:O19,12,FALSE) -> 18 | AB29: =VLOOKUP(B29,'ET-1B'!D1:P20,13,FALSE) -> 18 | AC29: =IF(COUNT($S29:$AB29)=0,"",SUM($S29:$AB29)) -> 162 | AD29: =IF(ISERROR(IF($AC29="","",ROUND(($AC29/$AC$10)*$AD$10,2))),"",IF($AC29="","",ROUND(($AC29/$AC$10)*$AD$10,2))) -> 81 | AE29: =IF($AD29="","",ROUND($AD29*$AE$10,2)) -> 32.4 | AF29: 93 | AG29: =IF(ISERROR(IF($AF29="","",ROUND(($AF29/$AF$10)*$AG$10,2))),"",IF($AF29="","",ROUND(($AF29/$AF$10)*$AG$10,2))) -> 93 | AH29: =IF($AG29="","",ROUND($AG29*$AH$10,2)) -> 18.6 | AI29: =IF(ISERROR(IF($AF29="","",ROUND(SUM($R29,$AE29,$AH29),2))),"",IF($AF29="","",ROUND(SUM($R29,$AE29,$AH29),2))) -> 95.48 | AJ29: =IF(ISERROR(IF($AF29="","",VLOOKUP(AI29,TRANSMUTATION_TABLE,4,TRUE))),"",IF($AF29="","",VLOOKUP(AI29,TRANSMUTATION_TABLE,4,TRUE))) -> 97
A30: 19 | B30: Sacdalan, Joshrie O. | F30: 39 | G30: 35 | H30: 22 | I30: 24 | J30: 33 | K30: 30 | L30: 34 | P30: =IF(COUNT($F30:$O30)=0,"",SUM($F30:$O30)) -> 217 | Q30: =IF(ISERROR(IF($P30="","",ROUND(($P30/$P$10)*$Q$10,2))),"",IF($P30="","",ROUND(($P30/$P$10)*$Q$10,2))) -> 74.83 | R30: =IF($Q30="","",ROUND($Q30*$R$10,2)) -> 44.9 | S30: =VLOOKUP(B30,'ET-1B'!D2:E21,2,FALSE) -> 18 | T30: =VLOOKUP(B30,'ET-1B'!D2:F21,3,FALSE) -> 18 | U30: =VLOOKUP(B30,'ET-1B'!D2:G21,4,FALSE) -> 18 | V30: =VLOOKUP(B30,'ET-1B'!D2:I21,6,FALSE) -> 20 | W30: =VLOOKUP(B30,'ET-1B'!D2:J21,7,FALSE) -> 20 | X30: =VLOOKUP(B30,'ET-1B'!D2:K21,8,FALSE) -> 18 | Y30: =VLOOKUP(B30,'ET-1B'!D2:L21,9,FALSE) -> 20 | Z30: =VLOOKUP(B30,'ET-1B'!D2:M21,10,FALSE) -> 20 | AA30: =VLOOKUP(B30,'ET-1B'!D2:O20,12,FALSE) -> 18 | AB30: =VLOOKUP(B30,'ET-1B'!D2:P21,13,FALSE) -> 20 | AC30: =IF(COUNT($S30:$AB30)=0,"",SUM($S30:$AB30)) -> 190 | AD30: =IF(ISERROR(IF($AC30="","",ROUND(($AC30/$AC$10)*$AD$10,2))),"",IF($AC30="","",ROUND(($AC30/$AC$10)*$AD$10,2))) -> 95 | AE30: =IF($AD30="","",ROUND($AD30*$AE$10,2)) -> 38 | AF30: 93 | AG30: =IF(ISERROR(IF($AF30="","",ROUND(($AF30/$AF$10)*$AG$10,2))),"",IF($AF30="","",ROUND(($AF30/$AF$10)*$AG$10,2))) -> 93 | AH30: =IF($AG30="","",ROUND($AG30*$AH$10,2)) -> 18.6 | AI30: =IF(ISERROR(IF($AF30="","",ROUND(SUM($R30,$AE30,$AH30),2))),"",IF($AF30="","",ROUND(SUM($R30,$AE30,$AH30),2))) -> 101.5 | AJ30: =IF(ISERROR(IF($AF30="","",VLOOKUP(AI30,TRANSMUTATION_TABLE,4,TRUE))),"",IF($AF30="","",VLOOKUP(AI30,TRANSMUTATION_TABLE,4,TRUE))) -> 100
A31: 20 | B31: Sangco, Jethro C. | F31: 30 | G31: 44 | H31: 26 | I31: 24 | J31: 27 | K31: 35 | L31: 33 | P31: =IF(COUNT($F31:$O31)=0,"",SUM($F31:$O31)) -> 219 | Q31: =IF(ISERROR(IF($P31="","",ROUND(($P31/$P$10)*$Q$10,2))),"",IF($P31="","",ROUND(($P31/$P$10)*$Q$10,2))) -> 75.52 | R31: =IF($Q31="","",ROUND($Q31*$R$10,2)) -> 45.31 | S31: =VLOOKUP(B31,'ET-1B'!D3:E22,2,FALSE) -> 18 | T31: =VLOOKUP(B31,'ET-1B'!D3:F22,3,FALSE) -> 18 | U31: =VLOOKUP(B31,'ET-1B'!D3:G22,4,FALSE) -> 18 | V31: =VLOOKUP(B31,'ET-1B'!D3:I22,6,FALSE) -> 0 | W31: =VLOOKUP(B31,'ET-1B'!D3:J22,7,FALSE) -> 20 | X31: =VLOOKUP(B31,'ET-1B'!D3:K22,8,FALSE) -> 18 | Y31: =VLOOKUP(B31,'ET-1B'!D3:L22,9,FALSE) -> 20 | Z31: =VLOOKUP(B31,'ET-1B'!D3:M22,10,FALSE) -> 20 | AA31: =VLOOKUP(B31,'ET-1B'!D3:O21,12,FALSE) -> 18 | AB31: =VLOOKUP(B31,'ET-1B'!D3:P22,13,FALSE) -> 20 | AC31: =IF(COUNT($S31:$AB31)=0,"",SUM($S31:$AB31)) -> 170 | AD31: =IF(ISERROR(IF($AC31="","",ROUND(($AC31/$AC$10)*$AD$10,2))),"",IF($AC31="","",ROUND(($AC31/$AC$10)*$AD$10,2))) -> 85 | AE31: =IF($AD31="","",ROUND($AD31*$AE$10,2)) -> 34 | AF31: 94 | AG31: =IF(ISERROR(IF($AF31="","",ROUND(($AF31/$AF$10)*$AG$10,2))),"",IF($AF31="","",ROUND(($AF31/$AF$10)*$AG$10,2))) -> 94 | AH31: =IF($AG31="","",ROUND($AG31*$AH$10,2)) -> 18.8 | AI31: =IF(ISERROR(IF($AF31="","",ROUND(SUM($R31,$AE31,$AH31),2))),"",IF($AF31="","",ROUND(SUM($R31,$AE31,$AH31),2))) -> 98.11 | AJ31: =IF(ISERROR(IF($AF31="","",VLOOKUP(AI31,TRANSMUTATION_TABLE,4,TRUE))),"",IF($AF31="","",VLOOKUP(AI31,TRANSMUTATION_TABLE,4,TRUE))) -> 98
A32: 21 | B32: Santiago, Jimrey B. | F32: 40 | G32: 45 | H32: 23 | I32: 28 | J32: 30 | K32: 20 | L32: 32 | P32: =IF(COUNT($F32:$O32)=0,"",SUM($F32:$O32)) -> 218 | Q32: =IF(ISERROR(IF($P32="","",ROUND(($P32/$P$10)*$Q$10,2))),"",IF($P32="","",ROUND(($P32/$P$10)*$Q$10,2))) -> 75.17 | R32: =IF($Q32="","",ROUND($Q32*$R$10,2)) -> 45.1 | S32: =VLOOKUP(B32,'ET-1B'!D4:E23,2,FALSE) -> #N/A | T32: =VLOOKUP(B32,'ET-1B'!D4:F23,3,FALSE) -> #N/A | U32: =VLOOKUP(B32,'ET-1B'!D4:G23,4,FALSE) -> #N/A | V32: =VLOOKUP(B32,'ET-1B'!D4:I23,6,FALSE) -> #N/A | W32: =VLOOKUP(B32,'ET-1B'!D4:J23,7,FALSE) -> #N/A | X32: =VLOOKUP(B32,'ET-1B'!D4:K23,8,FALSE) -> #N/A | Y32: =VLOOKUP(B32,'ET-1B'!D4:L23,9,FALSE) -> #N/A | Z32: =-VLOOKUP(B32,'ET-1B'!D4:M23,10,FALSE) -> #N/A | AA32: =VLOOKUP(B32,'ET-1B'!D4:O22,12,FALSE) -> #N/A | AB32: =VLOOKUP(B32,'ET-1B'!D4:P23,13,FALSE) -> #N/A | AC32: =IF(COUNT($S32:$AB32)=0,"",SUM($S32:$AB32)) | AD32: =IF(ISERROR(IF($AC32="","",ROUND(($AC32/$AC$10)*$AD$10,2))),"",IF($AC32="","",ROUND(($AC32/$AC$10)*$AD$10,2))) | AE32: =IF($AD32="","",ROUND($AD32*$AE$10,2)) | AF32: 94 | AG32: =IF(ISERROR(IF($AF32="","",ROUND(($AF32/$AF$10)*$AG$10,2))),"",IF($AF32="","",ROUND(($AF32/$AF$10)*$AG$10,2))) -> 94 | AH32: =IF($AG32="","",ROUND($AG32*$AH$10,2)) -> 18.8 | AI32: =IF(ISERROR(IF($AF32="","",ROUND(SUM($R32,$AE32,$AH32),2))),"",IF($AF32="","",ROUND(SUM($R32,$AE32,$AH32),2))) -> 63.9 | AJ32: =IF(ISERROR(IF($AF32="","",VLOOKUP(AI32,TRANSMUTATION_TABLE,4,TRUE))),"",IF($AF32="","",VLOOKUP(AI32,TRANSMUTATION_TABLE,4,TRUE))) -> 77
A33: 22 | B33: Ubalde, Ronald Aehron B. | F33: 40 | G33: 39 | H33: 21 | I33: 21 | J33: 29 | K33: 19 | L33: 30 | P33: =IF(COUNT($F33:$O33)=0,"",SUM($F33:$O33)) -> 199 | Q33: =IF(ISERROR(IF($P33="","",ROUND(($P33/$P$10)*$Q$10,2))),"",IF($P33="","",ROUND(($P33/$P$10)*$Q$10,2))) -> 68.62 | R33: =IF($Q33="","",ROUND($Q33*$R$10,2)) -> 41.17 | S33: =VLOOKUP(B33,'ET-1B'!D5:E24,2,FALSE) -> 18 | T33: =VLOOKUP(B33,'ET-1B'!D5:F24,3,FALSE) -> 18 | U33: =VLOOKUP(B33,'ET-1B'!D5:G24,4,FALSE) -> 18 | V33: =VLOOKUP(B33,'ET-1B'!D5:I24,6,FALSE) -> 18 | W33: =VLOOKUP(B33,'ET-1B'!D5:J24,7,FALSE) -> 20 | X33: =VLOOKUP(B33,'ET-1B'!D5:K24,8,FALSE) -> 0 | Y33: =VLOOKUP(B33,'ET-1B'!D5:L24,9,FALSE) -> 15 | Z33: =VLOOKUP(B33,'ET-1B'!D5:M24,10,FALSE) -> 20 | AA33: =VLOOKUP(B33,'ET-1B'!D5:O23,12,FALSE) -> 0 | AB33: =VLOOKUP(B33,'ET-1B'!D5:P24,13,FALSE) -> 20 | AC33: =IF(COUNT($S33:$AB33)=0,"",SUM($S33:$AB33)) -> 147 | AD33: =IF(ISERROR(IF($AC33="","",ROUND(($AC33/$AC$10)*$AD$10,2))),"",IF($AC33="","",ROUND(($AC33/$AC$10)*$AD$10,2))) -> 73.5 | AE33: =IF($AD33="","",ROUND($AD33*$AE$10,2)) -> 29.4 | AF33: 94 | AG33: =IF(ISERROR(IF($AF33="","",ROUND(($AF33/$AF$10)*$AG$10,2))),"",IF($AF33="","",ROUND(($AF33/$AF$10)*$AG$10,2))) -> 94 | AH33: =IF($AG33="","",ROUND($AG33*$AH$10,2)) -> 18.8 | AI33: =IF(ISERROR(IF($AF33="","",ROUND(SUM($R33,$AE33,$AH33),2))),"",IF($AF33="","",ROUND(SUM($R33,$AE33,$AH33),2))) -> 89.37 | AJ33: =IF(ISERROR(IF($AF33="","",VLOOKUP(AI33,TRANSMUTATION_TABLE,4,TRUE))),"",IF($AF33="","",VLOOKUP(AI33,TRANSMUTATION_TABLE,4,TRUE))) -> 93
A34: 23 | B34: Venezuela, Jhay-z Aaron M. | F34: 40 | G34: 40 | H34: 28 | I34: 20 | J34: 20 | K34: 15 | L34: 31 | P34: =IF(COUNT($F34:$O34)=0,"",SUM($F34:$O34)) -> 194 | Q34: =IF(ISERROR(IF($P34="","",ROUND(($P34/$P$10)*$Q$10,2))),"",IF($P34="","",ROUND(($P34/$P$10)*$Q$10,2))) -> 66.9 | R34: =IF($Q34="","",ROUND($Q34*$R$10,2)) -> 40.14 | S34: =VLOOKUP(B34,'ET-1B'!D6:E25,2,FALSE) -> #N/A | T34: =VLOOKUP(B34,'ET-1B'!D6:F25,3,FALSE) -> #N/A | U34: =VLOOKUP(B34,'ET-1B'!D6:G25,4,FALSE) -> #N/A | V34: =VLOOKUP(B34,'ET-1B'!D6:I25,6,FALSE) -> #N/A | W34: =VLOOKUP(B34,'ET-1B'!D6:J25,7,FALSE) -> #N/A | X34: =VLOOKUP(B34,'ET-1B'!D6:K25,8,FALSE) -> #N/A | Y34: =VLOOKUP(B34,'ET-1B'!D6:L25,9,FALSE) -> #N/A | Z34: =-VLOOKUP(B34,'ET-1B'!D6:M25,10,FALSE) -> #N/A | AA34: =VLOOKUP(B34,'ET-1B'!D6:O24,12,FALSE) -> #N/A | AB34: =VLOOKUP(B34,'ET-1B'!D6:P25,13,FALSE) -> #N/A | AC34: =IF(COUNT($S34:$AB34)=0,"",SUM($S34:$AB34)) | AD34: =IF(ISERROR(IF($AC34="","",ROUND(($AC34/$AC$10)*$AD$10,2))),"",IF($AC34="","",ROUND(($AC34/$AC$10)*$AD$10,2))) | AE34: =IF($AD34="","",ROUND($AD34*$AE$10,2)) | AF34: 95 | AG34: =IF(ISERROR(IF($AF34="","",ROUND(($AF34/$AF$10)*$AG$10,2))),"",IF($AF34="","",ROUND(($AF34/$AF$10)*$AG$10,2))) -> 95 | AH34: =IF($AG34="","",ROUND($AG34*$AH$10,2)) -> 19 | AI34: =IF(ISERROR(IF($AF34="","",ROUND(SUM($R34,$AE34,$AH34),2))),"",IF($AF34="","",ROUND(SUM($R34,$AE34,$AH34),2))) -> 59.14 | AJ34: =IF(ISERROR(IF($AF34="","",VLOOKUP(AI34,TRANSMUTATION_TABLE,4,TRUE))),"",IF($AF34="","",VLOOKUP(AI34,TRANSMUTATION_TABLE,4,TRUE))) -> 74
B35: Female
A36: 1 | B36: Abobo, Precious-Zennah B. | F36: 20 | G36: 30 | H36: 32 | I36: 30 | J36: 30 | K36: 31 | L36: 34 | P36: =IF(COUNT($F36:$O36)=0,"",SUM($F36:$O36)) -> 207 | Q36: =IF(ISERROR(IF($P36="","",ROUND(($P36/$P$10)*$Q$10,2))),"",IF($P36="","",ROUND(($P36/$P$10)*$Q$10,2))) -> 71.38 | R36: =IF($Q36="","",ROUND($Q36*$R$10,2)) -> 42.83 | S36: =VLOOKUP(B36,'ET-1B'!D1:E20,2,FALSE) -> 18 | T36: =VLOOKUP(B36,'ET-1B'!D1:F20,3,FALSE) -> 18 | U36: =VLOOKUP(B36,'ET-1B'!D1:G20,4,FALSE) -> 18 | V36: =VLOOKUP(B36,'ET-1B'!D1:I20,6,FALSE) -> 20 | W36: =VLOOKUP(B36,'ET-1B'!D1:J20,7,FALSE) -> 20 | X36: =VLOOKUP(B36,'ET-1B'!D1:K19,8,FALSE) -> 18 | Y36: =VLOOKUP(B36,'ET-1B'!D1:L20,9,FALSE) -> 20 | Z36: =VLOOKUP(B36,'ET-1B'!D1:M20,10,FALSE) -> 20 | AA36: =VLOOKUP(B36,'ET-1B'!D1:O20,12,FALSE) -> 18 | AB36: =VLOOKUP(B36,'ET-1B'!D1:P20,13,FALSE) -> 20 | AC36: =IF(COUNT($S36:$AB36)=0,"",SUM($S36:$AB36)) -> 190 | AD36: =IF(ISERROR(IF($AC36="","",ROUND(($AC36/$AC$10)*$AD$10,2))),"",IF($AC36="","",ROUND(($AC36/$AC$10)*$AD$10,2))) -> 95 | AE36: =IF($AD36="","",ROUND($AD36*$AE$10,2)) -> 38 | AF36: 98 | AG36: =IF(ISERROR(IF($AF36="","",ROUND(($AF36/$AF$10)*$AG$10,2))),"",IF($AF36="","",ROUND(($AF36/$AF$10)*$AG$10,2))) -> 98 | AH36: =IF($AG36="","",ROUND($AG36*$AH$10,2)) -> 19.6 | AI36: =IF(ISERROR(IF($AF36="","",ROUND(SUM($R36,$AE36,$AH36),2))),"",IF($AF36="","",ROUND(SUM($R36,$AE36,$AH36),2))) -> 100.43 | AJ36: =IF(ISERROR(IF($AF36="","",VLOOKUP(AI36,TRANSMUTATION_TABLE,4,TRUE))),"",IF($AF36="","",VLOOKUP(AI36,TRANSMUTATION_TABLE,4,TRUE))) -> 100
A37: 2 | B37: Agustin, Jackie Lyn C. | F37: 21 | G37: 20 | H37: 31 | I37: 35 | J37: 30 | K37: 31 | L37: 35 | P37: =IF(COUNT($F37:$O37)=0,"",SUM($F37:$O37)) -> 203 | Q37: =IF(ISERROR(IF($P37="","",ROUND(($P37/$P$10)*$Q$10,2))),"",IF($P37="","",ROUND(($P37/$P$10)*$Q$10,2))) -> 70 | R37: =IF($Q37="","",ROUND($Q37*$R$10,2)) -> 42 | S37: =VLOOKUP(B37,'ET-1B'!D2:E21,2,FALSE) -> 18 | T37: 20 | U37: 19 | V37: 19 | W37: 15 | X37: 20 | Y37: 15 | Z37: 17 | AA37: 18 | AB37: 19 | AC37: =IF(COUNT($S37:$AB37)=0,"",SUM($S37:$AB37)) -> 180 | AD37: =IF(ISERROR(IF($AC37="","",ROUND(($AC37/$AC$10)*$AD$10,2))),"",IF($AC37="","",ROUND(($AC37/$AC$10)*$AD$10,2))) -> 90 | AE37: =IF($AD37="","",ROUND($AD37*$AE$10,2)) -> 36 | AF37: 98 | AG37: =IF(ISERROR(IF($AF37="","",ROUND(($AF37/$AF$10)*$AG$10,2))),"",IF($AF37="","",ROUND(($AF37/$AF$10)*$AG$10,2))) -> 98 | AH37: =IF($AG37="","",ROUND($AG37*$AH$10,2)) -> 19.6 | AI37: =IF(ISERROR(IF($AF37="","",ROUND(SUM($R37,$AE37,$AH37),2))),"",IF($AF37="","",ROUND(SUM($R37,$AE37,$AH37),2))) -> 97.6 | AJ37: =IF(ISERROR(IF($AF37="","",VLOOKUP(AI37,TRANSMUTATION_TABLE,4,TRUE))),"",IF($AF37="","",VLOOKUP(AI37,TRANSMUTATION_TABLE,4,TRUE))) -> 98
A38: 3 | B38: Batchar, Loraine Zyrah O. | F38: 19 | G38: 41 | H38: 30 | I38: 20 | J38: 30 | K38: 35 | L38: 35 | P38: =IF(COUNT($F38:$O38)=0,"",SUM($F38:$O38)) -> 210 | Q38: =IF(ISERROR(IF($P38="","",ROUND(($P38/$P$10)*$Q$10,2))),"",IF($P38="","",ROUND(($P38/$P$10)*$Q$10,2))) -> 72.41 | R38: =IF($Q38="","",ROUND($Q38*$R$10,2)) -> 43.45 | S38: =VLOOKUP(B38,'ET-1B'!D3:E22,2,FALSE) -> #N/A | T38: 20 | U38: 19 | V38: 19 | W38: 17 | X38: 20 | Y38: 15 | Z38: 20 | AA38: 14 | AB38: 18 | AC38: =IF(COUNT($S38:$AB38)=0,"",SUM($S38:$AB38)) -> #N/A | AD38: =IF(ISERROR(IF($AC38="","",ROUND(($AC38/$AC$10)*$AD$10,2))),"",IF($AC38="","",ROUND(($AC38/$AC$10)*$AD$10,2))) | AE38: =IF($AD38="","",ROUND($AD38*$AE$10,2)) | AF38: 98 | AG38: =IF(ISERROR(IF($AF38="","",ROUND(($AF38/$AF$10)*$AG$10,2))),"",IF($AF38="","",ROUND(($AF38/$AF$10)*$AG$10,2))) -> 98 | AH38: =IF($AG38="","",ROUND($AG38*$AH$10,2)) -> 19.6 | AI38: =IF(ISERROR(IF($AF38="","",ROUND(SUM($R38,$AE38,$AH38),2))),"",IF($AF38="","",ROUND(SUM($R38,$AE38,$AH38),2))) -> 63.05 | AJ38: =IF(ISERROR(IF($AF38="","",VLOOKUP(AI38,TRANSMUTATION_TABLE,4,TRUE))),"",IF($AF38="","",VLOOKUP(AI38,TRANSMUTATION_TABLE,4,TRUE))) -> 76
A39: 4 | B39: Berches, Shaira A. | F39: 30 | G39: 25 | H39: 33 | I39: 35 | J39: 31 | K39: 27 | L39: 32 | P39: =IF(COUNT($F39:$O39)=0,"",SUM($F39:$O39)) -> 213 | Q39: =IF(ISERROR(IF($P39="","",ROUND(($P39/$P$10)*$Q$10,2))),"",IF($P39="","",ROUND(($P39/$P$10)*$Q$10,2))) -> 73.45 | R39: =IF($Q39="","",ROUND($Q39*$R$10,2)) -> 44.07 | S39: =VLOOKUP(B39,'ET-1B'!D4:E23,2,FALSE) -> #N/A | T39: 20 | U39: 18 | V39: 20 | W39: 17 | X39: 20 | Y39: 16 | Z39: 20 | AA39: 14 | AB39: 18 | AC39: =IF(COUNT($S39:$AB39)=0,"",SUM($S39:$AB39)) -> #N/A | AD39: =IF(ISERROR(IF($AC39="","",ROUND(($AC39/$AC$10)*$AD$10,2))),"",IF($AC39="","",ROUND(($AC39/$AC$10)*$AD$10,2))) | AE39: =IF($AD39="","",ROUND($AD39*$AE$10,2)) | AF39: 97 | AG39: =IF(ISERROR(IF($AF39="","",ROUND(($AF39/$AF$10)*$AG$10,2))),"",IF($AF39="","",ROUND(($AF39/$AF$10)*$AG$10,2))) -> 97 | AH39: =IF($AG39="","",ROUND($AG39*$AH$10,2)) -> 19.4 | AI39: =IF(ISERROR(IF($AF39="","",ROUND(SUM($R39,$AE39,$AH39),2))),"",IF($AF39="","",ROUND(SUM($R39,$AE39,$AH39),2))) -> 63.47 | AJ39: =IF(ISERROR(IF($AF39="","",VLOOKUP(AI39,TRANSMUTATION_TABLE,4,TRUE))),"",IF($AF39="","",VLOOKUP(AI39,TRANSMUTATION_TABLE,4,TRUE))) -> 77
A40: 5 | B40: Dajuya, Rachel P. | F40: 30 | G40: 30 | H40: 30 | I40: 25 | J40: 31 | K40: 33 | L40: 33 | P40: =IF(COUNT($F40:$O40)=0,"",SUM($F40:$O40)) -> 212 | Q40: =IF(ISERROR(IF($P40="","",ROUND(($P40/$P$10)*$Q$10,2))),"",IF($P40="","",ROUND(($P40/$P$10)*$Q$10,2))) -> 73.1 | R40: =IF($Q40="","",ROUND($Q40*$R$10,2)) -> 43.86 | S40: =VLOOKUP(B40,'ET-1B'!D5:E24,2,FALSE) -> 18 | T40: 20 | U40: 18 | V40: 20 | W40: 17 | X40: 20 | Y40: 16 | Z40: 20 | AA40: 12 | AB40: 17 | AC40: =IF(COUNT($S40:$AB40)=0,"",SUM($S40:$AB40)) -> 178 | AD40: =IF(ISERROR(IF($AC40="","",ROUND(($AC40/$AC$10)*$AD$10,2))),"",IF($AC40="","",ROUND(($AC40/$AC$10)*$AD$10,2))) -> 89 | AE40: =IF($AD40="","",ROUND($AD40*$AE$10,2)) -> 35.6 | AF40: 97 | AG40: =IF(ISERROR(IF($AF40="","",ROUND(($AF40/$AF$10)*$AG$10,2))),"",IF($AF40="","",ROUND(($AF40/$AF$10)*$AG$10,2))) -> 97 | AH40: =IF($AG40="","",ROUND($AG40*$AH$10,2)) -> 19.4 | AI40: =IF(ISERROR(IF($AF40="","",ROUND(SUM($R40,$AE40,$AH40),2))),"",IF($AF40="","",ROUND(SUM($R40,$AE40,$AH40),2))) -> 98.86 | AJ40: =IF(ISERROR(IF($AF40="","",VLOOKUP(AI40,TRANSMUTATION_TABLE,4,TRUE))),"",IF($AF40="","",VLOOKUP(AI40,TRANSMUTATION_TABLE,4,TRUE))) -> 99
A41: 6 | B41: Dionisio, Michaella M. | F41: 35 | G41: 30 | H41: 23 | I41: 31 | J41: 32 | K41: 33 | L41: 34 | P41: =IF(COUNT($F41:$O41)=0,"",SUM($F41:$O41)) -> 218 | Q41: =IF(ISERROR(IF($P41="","",ROUND(($P41/$P$10)*$Q$10,2))),"",IF($P41="","",ROUND(($P41/$P$10)*$Q$10,2))) -> 75.17 | R41: =IF($Q41="","",ROUND($Q41*$R$10,2)) -> 45.1 | S41: =VLOOKUP(B41,'ET-1B'!D6:E25,2,FALSE) -> 18 | T41: 18 | U41: 20 | V41: 16 | W41: 20 | X41: 17 | Y41: 17 | Z41: 20 | AA41: 12 | AB41: 17 | AC41: =IF(COUNT($S41:$AB41)=0,"",SUM($S41:$AB41)) -> 175 | AD41: =IF(ISERROR(IF($AC41="","",ROUND(($AC41/$AC$10)*$AD$10,2))),"",IF($AC41="","",ROUND(($AC41/$AC$10)*$AD$10,2))) -> 87.5 | AE41: =IF($AD41="","",ROUND($AD41*$AE$10,2)) -> 35 | AF41: 97 | AG41: =IF(ISERROR(IF($AF41="","",ROUND(($AF41/$AF$10)*$AG$10,2))),"",IF($AF41="","",ROUND(($AF41/$AF$10)*$AG$10,2))) -> 97 | AH41: =IF($AG41="","",ROUND($AG41*$AH$10,2)) -> 19.4 | AI41: =IF(ISERROR(IF($AF41="","",ROUND(SUM($R41,$AE41,$AH41),2))),"",IF($AF41="","",ROUND(SUM($R41,$AE41,$AH41),2))) -> 99.5 | AJ41: =IF(ISERROR(IF($AF41="","",VLOOKUP(AI41,TRANSMUTATION_TABLE,4,TRUE))),"",IF($AF41="","",VLOOKUP(AI41,TRANSMUTATION_TABLE,4,TRUE))) -> 99
A42: 7 | B42: Dirige, Rashlie Jhem F. | F42: 25 | G42: 30 | H42: 34 | I42: 32 | J42: 32 | K42: 34 | L42: 30 | P42: =IF(COUNT($F42:$O42)=0,"",SUM($F42:$O42)) -> 217 | Q42: =IF(ISERROR(IF($P42="","",ROUND(($P42/$P$10)*$Q$10,2))),"",IF($P42="","",ROUND(($P42/$P$10)*$Q$10,2))) -> 74.83 | R42: =IF($Q42="","",ROUND($Q42*$R$10,2)) -> 44.9 | S42: =VLOOKUP(B42,'ET-1B'!D7:E26,2,FALSE) -> #N/A | T42: 18 | U42: 20 | V42: 16 | W42: 20 | X42: 15 | Y42: 17 | Z42: 20 | AA42: 13 | AB42: 16 | AC42: =IF(COUNT($S42:$AB42)=0,"",SUM($S42:$AB42)) -> #N/A | AD42: =IF(ISERROR(IF($AC42="","",ROUND(($AC42/$AC$10)*$AD$10,2))),"",IF($AC42="","",ROUND(($AC42/$AC$10)*$AD$10,2))) | AE42: =IF($AD42="","",ROUND($AD42*$AE$10,2)) | AF42: 96 | AG42: =IF(ISERROR(IF($AF42="","",ROUND(($AF42/$AF$10)*$AG$10,2))),"",IF($AF42="","",ROUND(($AF42/$AF$10)*$AG$10,2))) -> 96 | AH42: =IF($AG42="","",ROUND($AG42*$AH$10,2)) -> 19.2 | AI42: =IF(ISERROR(IF($AF42="","",ROUND(SUM($R42,$AE42,$AH42),2))),"",IF($AF42="","",ROUND(SUM($R42,$AE42,$AH42),2))) -> 64.1 | AJ42: =IF(ISERROR(IF($AF42="","",VLOOKUP(AI42,TRANSMUTATION_TABLE,4,TRUE))),"",IF($AF42="","",VLOOKUP(AI42,TRANSMUTATION_TABLE,4,TRUE))) -> 77
...
